2020-12-02 10:39:36,831 dellemc_isilon_gatherfacts.py INFO : Got python SDK instance for provisioning on Isilon 
2020-12-02 10:41:47,141 connectionpool.py WARNING : Retrying (Retry(total=2, connect=None, read=None, redirect=None, status=None)) after connection broken by 'NewConnectionError('<urllib3.connection.HTTPSConnection object at 0x7f7a12357198>: Failed to establish a new connection: [Errno 110] Connection timed out',)': /session/1/session
2020-12-02 10:43:58,212 connectionpool.py WARNING : Retrying (Retry(total=1, connect=None, read=None, redirect=None, status=None)) after connection broken by 'NewConnectionError('<urllib3.connection.HTTPSConnection object at 0x7f7a12357390>: Failed to establish a new connection: [Errno 110] Connection timed out',)': /session/1/session
2020-12-02 10:46:09,285 connectionpool.py WARNING : Retrying (Retry(total=0, connect=None, read=None, redirect=None, status=None)) after connection broken by 'NewConnectionError('<urllib3.connection.HTTPSConnection object at 0x7f7a12357630>: Failed to establish a new connection: [Errno 110] Connection timed out',)': /session/1/session
2020-12-02 10:48:20,357 dellemc_isilon_gatherfacts.py ERROR : Get Attributes List for Isilon cluster: 192.168.3.11 failed with error: HTTPSConnectionPool(host='192.168.3.11', port=8080): Max retries exceeded with url: /session/1/session (Caused by NewConnectionError('<urllib3.connection.HTTPSConnection object at 0x7f7a128255c0>: Failed to establish a new connection: [Errno 110] Connection timed out',))
